Workbook

Sheet Summary PO Permit
A1: Summary PO RT/RW (CLUSTER NAME)
A2: Permit | B2: 7650000
A3: (Permit + PPh 2.65%) | B3: =B2+(B2*2.65%) -> 7852725

Sheet BoQ NRO Cluster
A1: DISTRIBUSI - SUBFEEEDER | N1: AS PLAN
A2: BOQ GPON FTTH FOR OPTICAL DISTRIBUTION NETWORK (ODN) | N2: OLT Name
A3: PT. EKA MAS REPUBLIK ODN, OSP, Aktivasi, Instalasi, Integrasi, Testing & Dokumentasi | N3: Cluster
A4: PROJECT ROLL OUT 2024 | N4: Net Type | O4: Aerial
N5: HP
A6: No | B6: Description/Item | C6: Unit | D6: Material Qty | E6: Service Qty | F6: Material Price | G6: Service Price | H6: Total Material Price | I6: Total Service Price | J6: Total Price | M6: Koreksi No Material | N6: No Material | O6: Short Text/Description SAP | P6: Remarks | Q6: Service
A7: 1 | B7: Pengamanan & Persiapan
A8: 1.1 | B8: Pengamanan Perizinan dan K3 | C8: ls | E8: 1 | L8: =F8+G8 -> 0 | N8: 500004774 | O8: PENGAMANAN PERIZINAN DAN K3 (Cluster Only) | P8: Material | Q8: Vendor
A9: 1.2 | B9: Transportasi, Mobilisasi & demobilisasi | C9: ls | E9: 1 | H9: =D9*F9 -> 0 | K9: =D9+E9 -> 1 | L9: =F9+G9 -> 0 | N9: 500003890 | O9: TRANSPORTASI, MOBILISASI DAN DEMOBILISASI | P9: Material | Q9: Vendor
A10: Sub Total Preparation | H10: =SUM(H8:H8) -> 0 | I10: =SUM(I8:I8) -> 0 | J10: =H10+I10 -> 0
A12: 2 | B12: ODN, OSP, Aktivasi, Instalasi, termasuk ATP Civil Work, Integrasi, Testing & Dokumentasi
A13: 2.1 | B13: ODN
A14: A | B14: FO core type SM G.652.D-ADSS (Aerial dan Underground)
B15: FO core type SM G.652.D-ADSS 24 cores | C15: meter | D15: =SUM('BoM AE'!C16:C19) -> 0 | H15: =D15*F15 -> 0 | I15: =E15*G15 -> 0 | K15: =D15+E15 -> 0 | L15: =F15+G15 -> 0 | N15: 200000100 | O15: FO TYPE SM G.652.D-ADSS 24 CORES | P15: Material | Q15: Internal
B16: Instal FO core type SM G.652.D-ADSS 24 cores | C16: meter | E16: =D15 -> 0 | H16: =D16*F16 -> 0 | I16: =E16*G16 -> 0 | K16: =D16+E16 -> 0 | L16: =F16+G16 -> 0 | N16: 500002050 | O16: INSTAL FO TYPE SM G.652.D-ADSS 24 CORES | P16: Service | Q16: Vendor
B17: FO core type SM G.652.D-ADSS 36 cores | C17: meter | D17: =SUM('BoM AE'!C20:C23) -> 0 | H17: =D17*F17 -> 0 | I17: =E17*G17 -> 0 | K17: =D17+E17 -> 0 | L17: =F17+G17 -> 0 | N17: 200000975 | O17: FO TYPE SM G.652.D-ADSS 36 CORES | P17: Material | Q17: Internal
B18: Instal FO core type SM G.652.D-ADSS 36 cores | C18: meter | E18: =D17 -> 0 | H18: =D18*F18 -> 0 | I18: =E18*G18 -> 0 | K18: =D18+E18 -> 0 | L18: =F18+G18 -> 0 | N18: 500002051 | O18: INSTAL FO TYPE SM G.652.D-ADSS 36 CORES | P18: Service | Q18: Vendor
B19: FO core type SM G.652.D-ADSS 48 cores | C19: meter | D19: =E20 -> 0 | H19: =D19*F19 -> 0 | I19: =E19*G19 -> 0 | K19: =D19+E19 -> 0 | L19: =F19+G19 -> 0 | N19: 200001038 | O19: FO TYPE SM G.652.D-ADSS 48 CORES | P19: Material | Q19: Internal
B20: Instal FO core type SM G.652.D-ADSS 48 cores | C20: meter | E20: =SUM('BoM AE'!C24:C27) -> 0 | H20: =D20*F20 -> 0 | I20: =E20*G20 -> 0 | K20: =D20+E20 -> 0 | L20: =F20+G20 -> 0 | N20: 500002052 | O20: INSTAL FO TYPE SM G.652.D-ADSS 48 CORES | P20: Service | Q20: Vendor
B21: FO core type SM G.652.D-ADSS 72 cores | C21: meter | N21: 200001970 | O21: FO TYPE SM G.652.D-ADSS 72 CORES | P21: Material | Q21: Internal
B22: Instal FO core type SM G.652.D-ADSS 72 cores | C22: meter | N22: 500003410 | O22: INSTAL FO TYPE SM G.652.D-ADSS 72 CORES | P22: Service | Q22: Vendor
B23: FO core type SM G.652.D-ADSS 96 cores | C23: meter | N23: 200001630 | O23: FO TYPE SM G.652.D-ADSS 96 CORES | P23: Material | Q23: Internal
B24: Instal FO core type SM G.652.D-ADSS 96 cores | C24: meter | N24: 500002890 | O24: INSTAL FO TYPE SM G.652.D-ADSS 96 CORES | P24: Service | Q24: Vendor
B25: FO core type SM G.652.D-ADSS 144 cores | C25: meter | H25: =D25*F25 -> 0 | I25: =E25*G25 -> 0 | K25: =D25+E25 -> 0 | L25: =F25+G25 -> 0 | N25: 200001030 | O25: FO TYPE SM G.652.D-ADSS 144 CORES | P25: Material | Q25: Internal
B26: Instal FO core type SM G.652.D-ADSS 144 cores | C26: meter | H26: =D26*F26 -> 0 | I26: =E26*G26 -> 0 | K26: =D26+E26 -> 0 | L26: =F26+G26 -> 0 | N26: 500002088 | O26: INSTAL FO TYPE SM G.652.D-ADSS 144 CORES | P26: Service | Q26: Vendor
B27: FO core type SM G.652.D-ADSS 288 cores | C27: meter | H27: =D27*F27 -> 0 | I27: =E27*G27 -> 0 | K27: =D27+E27 -> 0 | L27: =F27+G27 -> 0 | N27: 200001015 | O27: FO TYPE SM G.652.D-ADSS 288 CORES | P27: Material | Q27: Internal
B28: Instal FO core type SM G.652.D-ADSS 288 cores | C28: meter | H28: =D28*F28 -> 0 | I28: =E28*G28 -> 0 | K28: =D28+E28 -> 0 | L28: =F28+G28 -> 0 | N28: 500002089 | O28: INSTAL FO TYPE SM G.652.D-ADSS 288 CORES | P28: Service | Q28: Vendor
B29: Round Cable 1C - 50 m | C29: set | N29: 200002668 | O29: ROUND CABLE 1C - 50 M | P29: Material
B30: Install Round Cable 1C - 50 m | C30: set | N30: 500004722 | O30: INSTALL ROUND CABLE 1C - 50 M | P30: Service
B31: Round Cable 1C - 100 m | C31: set | N31: 200002669 | O31: ROUND CABLE 1C - 100 M | P31: Material
B32: Install Round Cable 1C - 100 m | C32: set | N32: 500004723 | O32: INSTALL ROUND CABLE 1C - 100 M | P32: Service
B33: Round Cable 1C - 150 m | C33: set | N33: 200002670 | O33: ROUND CABLE 1C - 150 M | P33: Material
B34: Install Round Cable 1C - 150 m | C34: set | N34: 500004724 | O34: INSTALL ROUND CABLE 1C - 150 M | P34: Service
B35: Round Cable 1C - 200 m | C35: set | N35: 200002671 | O35: ROUND CABLE 1C - 200 M | P35: Material
B36: Install Round Cable 1C - 200 m | C36: set | N36: 500004725 | O36: INSTALL ROUND CABLE 1C - 200 M | P36: Service
B37: Round Cable 1C - 250 m | C37: set | N37: 200002713 | O37: ROUND CABLE 1C - 250 M | P37: Material
B38: Install Round Cable 1C - 250 m | C38: set | N38: 500004777 | O38: INSTALL ROUND CABLE 1C - 250 M | P38: Service
B39: Round Cable 1C - 300 m | C39: set | N39: 200002714 | O39: ROUND CABLE 1C - 300 M | P39: Material
B40: Install Round Cable 1C - 300 m | C40: set | N40: 500004778 | O40: INSTALL ROUND CABLE 1C - 300 M | P40: Service
A41: B | B41: Fiber Distribution Terminal (FDT) SC/APC c/w Box, matrix terminal, Patchtray, Pigtail, label & accessories include concrete base | H41: =D41*F41 -> 0 | I41: =E41*G41 -> 0 | K41: =D41+E41 -> 0 | L41: =F41+G41 -> 0
...

Sheet BoQ NRO All Feeder
A1: DISTRIBUSI - SUBFEEEDER | N1: AS PLAN
A2: BOQ GPON FTTH FOR OPTICAL DISTRIBUTION NETWORK (ODN) | N2: OLT Name | O2: XXX
A3: PT. EKA MAS REPUBLIK ODN, OSP, Aktivasi, Instalasi, Integrasi, Testing & Dokumentasi | N3: Cluster | O3: XXX
A4: PROJECT ROLL OUT 2024 | N4: Net Type | O4: Aerial
N5: HP | O5: XXX
A6: No | B6: Description/Item | C6: Unit | D6: Material Qty | E6: Service Qty | F6: Material Price | G6: Service Price | H6: Total Material Price | I6: Total Service Price | J6: Total Price | M6: Koreksi No Material | N6: No Material | O6: Short Text/Description SAP | P6: Remarks | Q6: Service
A7: 1 | B7: Pengamanan & Persiapan
A8: 1.1 | B8: Pengamanan & Persiapan (Kesehatan dan Keselamatan Kerja) | C8: ls | E8: 1 | H8: =#REF!*F8 -> #REF! | K8: =#REF!+D8 -> #REF! | L8: =F8+G8 -> 0 | N8: 500003800 | O8: PENGAMANAN & PERSIAPAN | P8: Material | Q8: Vendor
A9: 1.2 | B9: Transportasi, Mobilisasi & demobilisasi | C9: ls | E9: 1 | H9: =D9*F9 -> 0 | K9: =D9+E9 -> 1 | L9: =F9+G9 -> 0 | N9: 500003890 | O9: TRANSPORTASI, MOBILISASI DAN DEMOBILISASI | P9: Material | Q9: Vendor
A10: Sub Total Preparation | H10: =SUM(H8:H8) -> #REF! | I10: =SUM(I8:I8) -> 0 | J10: =H10+I10 -> #REF!
A12: 2 | B12: ODN, OSP, Aktivasi, Instalasi, termasuk ATP Civil Work, Integrasi, Testing & Dokumentasi
A13: 2.1 | B13: ODN
A14: A | B14: FO core type SM G.652.D-ADSS (Aerial dan Underground)
B15: FO core type SM G.652.D-ADSS 24 cores | C15: meter | D15: =E16 -> 0 | H15: =D15*F15 -> 0 | I15: =E15*G15 -> 0 | K15: =D15+E15 -> 0 | L15: =F15+G15 -> 0 | N15: 200000100 | O15: FO TYPE SM G.652.D-ADSS 24 CORES | P15: Material | Q15: Internal
B16: Instal FO core type SM G.652.D-ADSS 24 cores | C16: meter | E16: =SUM('BoM AE'!O9) -> 0 | H16: =D16*F16 -> 0 | I16: =E16*G16 -> 0 | K16: =D16+E16 -> 0 | L16: =F16+G16 -> 0 | N16: 500002050 | O16: INSTAL FO TYPE SM G.652.D-ADSS 24 CORES | P16: Service | Q16: Vendor
B17: FO core type SM G.652.D-ADSS 36 cores | C17: meter | D17: =E18 -> 0 | H17: =D17*F17 -> 0 | I17: =E17*G17 -> 0 | K17: =D17+E17 -> 0 | L17: =F17+G17 -> 0 | N17: 200000975 | O17: FO TYPE SM G.652.D-ADSS 36 CORES | P17: Material | Q17: Internal
B18: Instal FO core type SM G.652.D-ADSS 36 cores | C18: meter | E18: =SUM('BoM AE'!O10) -> 0 | H18: =D18*F18 -> 0 | I18: =E18*G18 -> 0 | K18: =D18+E18 -> 0 | L18: =F18+G18 -> 0 | N18: 500002051 | O18: INSTAL FO TYPE SM G.652.D-ADSS 36 CORES | P18: Service | Q18: Vendor
B19: FO core type SM G.652.D-ADSS 48 cores | C19: meter | D19: =E20 -> 0 | H19: =D19*F19 -> 0 | I19: =E19*G19 -> 0 | K19: =D19+E19 -> 0 | L19: =F19+G19 -> 0 | N19: 200001038 | O19: FO TYPE SM G.652.D-ADSS 48 CORES | P19: Material | Q19: Internal
B20: Instal FO core type SM G.652.D-ADSS 48 cores | C20: meter | E20: =SUM('BoM AE'!O11) -> 0 | H20: =D20*F20 -> 0 | I20: =E20*G20 -> 0 | K20: =D20+E20 -> 0 | L20: =F20+G20 -> 0 | N20: 500002052 | O20: INSTAL FO TYPE SM G.652.D-ADSS 48 CORES | P20: Service | Q20: Vendor
B21: FO core type SM G.652.D-ADSS 72 cores | C21: meter | D21: =E22 -> 0 | N21: 200001970 | O21: FO TYPE SM G.652.D-ADSS 72 CORES | P21: Material | Q21: Internal
B22: Instal FO core type SM G.652.D-ADSS 72 cores | C22: meter | E22: =SUM('BoM AE'!O12) -> 0 | N22: 500003410 | O22: INSTAL FO TYPE SM G.652.D-ADSS 72 CORES | P22: Service | Q22: Vendor
B23: FO core type SM G.652.D-ADSS 96 cores | C23: meter | D23: =E24 -> 0 | N23: 200001630 | O23: FO TYPE SM G.652.D-ADSS 96 CORES | P23: Material | Q23: Internal
B24: Instal FO core type SM G.652.D-ADSS 96 cores | C24: meter | E24: =SUM('BoM AE'!O13) -> 0 | N24: 500002890 | O24: INSTAL FO TYPE SM G.652.D-ADSS 96 CORES | P24: Service | Q24: Vendor
B25: FO core type SM G.652.D-ADSS 144 cores | C25: meter | D25: =E26 -> 0 | H25: =D25*F25 -> 0 | I25: =E25*G25 -> 0 | K25: =D25+E25 -> 0 | L25: =F25+G25 -> 0 | N25: 200001030 | O25: FO TYPE SM G.652.D-ADSS 144 CORES | P25: Material | Q25: Internal
B26: Instal FO core type SM G.652.D-ADSS 144 cores | C26: meter | E26: =SUM('BoM AE'!O14) -> 0 | H26: =D26*F26 -> 0 | I26: =E26*G26 -> 0 | K26: =D26+E26 -> 0 | L26: =F26+G26 -> 0 | N26: 500002088 | O26: INSTAL FO TYPE SM G.652.D-ADSS 144 CORES | P26: Service | Q26: Vendor
B27: FO core type SM G.652.D-ADSS 288 cores | C27: meter | D27: =E28 -> 0 | H27: =D27*F27 -> 0 | I27: =E27*G27 -> 0 | K27: =D27+E27 -> 0 | L27: =F27+G27 -> 0 | N27: 200001015 | O27: FO TYPE SM G.652.D-ADSS 288 CORES | P27: Material | Q27: Internal
B28: Instal FO core type SM G.652.D-ADSS 288 cores | C28: meter | E28: =SUM('BoM AE'!O15) -> 0 | H28: =D28*F28 -> 0 | I28: =E28*G28 -> 0 | K28: =D28+E28 -> 0 | L28: =F28+G28 -> 0 | N28: 500002089 | O28: INSTAL FO TYPE SM G.652.D-ADSS 288 CORES | P28: Service | Q28: Vendor
B29: Round Cable 1C - 50 m | C29: set | N29: 200002668 | O29: ROUND CABLE 1C - 50 M | P29: Material
B30: Install Round Cable 1C - 50 m | C30: set | N30: 500004722 | O30: INSTALL ROUND CABLE 1C - 50 M | P30: Service
B31: Round Cable 1C - 100 m | C31: set | N31: 200002669 | O31: ROUND CABLE 1C - 100 M | P31: Material
B32: Install Round Cable 1C - 100 m | C32: set | N32: 500004723 | O32: INSTALL ROUND CABLE 1C - 100 M | P32: Service
B33: Round Cable 1C - 150 m | C33: set | N33: 200002670 | O33: ROUND CABLE 1C - 150 M | P33: Material
B34: Install Round Cable 1C - 150 m | C34: set | N34: 500004724 | O34: INSTALL ROUND CABLE 1C - 150 M | P34: Service
B35: Round Cable 1C - 200 m | C35: set | N35: 200002671 | O35: ROUND CABLE 1C - 200 M | P35: Material
B36: Install Round Cable 1C - 200 m | C36: set | N36: 500004725 | O36: INSTALL ROUND CABLE 1C - 200 M | P36: Service
B37: Round Cable 1C - 250 m | C37: set | N37: 200002713 | O37: ROUND CABLE 1C - 250 M | P37: Material
B38: Install Round Cable 1C - 250 m | C38: set | N38: 500004777 | O38: INSTALL ROUND CABLE 1C - 250 M | P38: Service
B39: Round Cable 1C - 300 m | C39: set | N39: 200002714 | O39: ROUND CABLE 1C - 300 M | P39: Material
B40: Install Round Cable 1C - 300 m | C40: set | N40: 500004778 | O40: INSTALL ROUND CABLE 1C - 300 M | P40: Service
A41: B | B41: Fiber Distribution Terminal (FDT) SC/APC c/w Box, matrix terminal, Patchtray, Pigtail, label & accessories include concrete base | H41: =D41*F41 -> 0 | I41: =E41*G41 -> 0 | K41: =D41+E41 -> 0 | L41: =F41+G41 -> 0
...

Sheet BoM AE
A1: BoM Cluster - | B1: ='BoQ NRO Cluster'!O3 -> 0 | C1: Qty | D1: FDT 1 | E1: FDT 2 | F1: FDT 3 | G1: FDT 4 | H1: FDT 5 | I1: Unit | J1: Remarks | M1: BoM - Main/Hub/Sub Feeder | N1: =B1 -> 0 | O1: Qty | P1: FDT 1 | Q1: FDT 2 | R1: FDT 3 | S1: FDT 4 | T1: FDT 5 | U1: Units | V1: Remarks
A2: Total Rute | B2: Line A - 24C/2T | C2: =SUM(D2:H2) -> 0 | D2: 0 | E2: 0 | F2: 0 | I2: m | J2: qty based on design | M2: Total Route to FDT | N2: 24C/2T | O2: =SUM(P2:T2) -> 0 | U2: m | V2: qty based on design
B3: Line B - 24C/2T | C3: =SUM(D3:H3) -> 0 | D3: 0 | F3: 0 | I3: m | J3: qty based on design | N3: 36C/3T | O3: =SUM(P3:T3) -> 0 | U3: m | V3: qty based on design
B4: Line C - 24C/2T | C4: =SUM(D4:H4) -> 0 | I4: m | J4: qty based on design | N4: 48C/4T | O4: =SUM(P4:T4) -> 0 | U4: m | V4: qty based on design
B5: Line D - 24C/2T | C5: =SUM(D5:H5) -> 0 | I5: m | J5: qty based on design | N5: 72C/6T | O5: =SUM(P5:T5) -> 0 | U5: m | V5: qty based on design
B6: Line A - 36C/3T | C6: =SUM(D6:H6) -> 0 | D6: 0 | I6: m | J6: qty based on design | N6: 96C/8T | O6: =SUM(P6:T6) -> 0 | U6: m | V6: qty based on design
B7: Line B - 36C/3T | C7: =SUM(D7:H7) -> 0 | D7: 0 | I7: m | J7: qty based on design | N7: 144C/12T | O7: =SUM(P7:T7) -> 0 | U7: m | V7: auto based on formula
B8: Line C - 36C/3T | C8: =SUM(D8:H8) -> 0 | I8: m | J8: qty based on design | N8: 288C/24T | O8: =SUM(P8:T8) -> 0 | U8: m | V8: auto based on formula
B9: Line D - 36C/3T | C9: =SUM(D9:H9) -> 0 | I9: m | J9: qty based on design | M9: Total Panjang Kabel to FDT (Slack + toleransi 5%) | N9: =N2 -> 24C/2T | O9: =SUM(P9:T9) -> 0 | P9: =ROUNDUP(((P2)+(P16*20))*1.05,0) -> 0 | Q9: =ROUNDUP(((Q2)+(Q16*20))*1.05,0) -> 0 | R9: =ROUNDUP(((R2)+(R16*20))*1.05,0) -> 0 | S9: =ROUNDUP(((S2)+(S16*20))*1.05,0) -> 0 | T9: =ROUNDUP(((T2)+(T16*20))*1.05,0) -> 0 | U9: m | V9: auto based on formula
B10: Line A - 48C/4T | C10: =SUM(D10:H10) -> 0 | I10: m | J10: qty based on design | N10: =N3 -> 36C/3T | O10: =SUM(P10:T10) -> 0 | P10: =ROUNDUP(((P3)+(P17*20))*1.05,0) -> 0 | Q10: =ROUNDUP(((Q3)+(Q17*20))*1.05,0) -> 0 | R10: =ROUNDUP(((R3)+(R17*20))*1.05,0) -> 0 | S10: =ROUNDUP(((S3)+(S17*20))*1.05,0) -> 0 | T10: =ROUNDUP(((T3)+(T17*20))*1.05,0) -> 0 | U10: m | V10: auto based on formula
B11: Line B - 48C/4T | C11: =SUM(D11:H11) -> 0 | I11: m | J11: qty based on design | N11: =N4 -> 48C/4T | O11: =SUM(P11:T11) -> 0 | P11: =ROUNDUP(((P4)+(P18*20))*1.05,0) -> 0 | Q11: =ROUNDUP(((Q4)+(Q18*20))*1.05,0) -> 0 | R11: =ROUNDUP(((R4)+(R18*20))*1.05,0) -> 0 | S11: =ROUNDUP(((S4)+(S18*20))*1.05,0) -> 0 | T11: =ROUNDUP(((T4)+(T18*20))*1.05,0) -> 0 | U11: m | V11: auto based on formula
B12: Line C - 48C/4T | C12: =SUM(D12:H12) -> 0 | I12: m | J12: qty based on design | N12: 72C/6T | O12: =SUM(P12:T12) -> 0 | P12: =ROUNDUP(((P5)+(P19*20))*1.05,0) -> 0 | Q12: =ROUNDUP(((Q5)+(Q19*20))*1.05,0) -> 0 | R12: =ROUNDUP(((R5)+(R19*20))*1.05,0) -> 0 | S12: =ROUNDUP(((S5)+(S19*20))*1.05,0) -> 0 | T12: =ROUNDUP(((T5)+(T19*20))*1.05,0) -> 0 | U12: m | V12: auto based on formula
B13: Line D - 48C/4T | C13: =SUM(D13:H13) -> 0 | I13: m | J13: qty based on design | N13: 96C/8T | O13: =SUM(P13:T13) -> 0 | P13: =ROUNDUP(((P6)+(P20*20))*1.05,0) -> 0 | Q13: =ROUNDUP(((Q6)+(Q20*20))*1.05,0) -> 0 | R13: =ROUNDUP(((R6)+(R20*20))*1.05,0) -> 0 | S13: =ROUNDUP(((S6)+(S20*20))*1.05,0) -> 0 | T13: =ROUNDUP(((T6)+(T20*20))*1.05,0) -> 0 | U13: m | V13: auto based on formula
A14: Total Rute | C14: =SUM(D14:H14) -> 0 | D14: =SUM(D2:D13) -> 0 | E14: =SUM(E2:E13) -> 0 | F14: =SUM(F2:F13) -> 0 | G14: =SUM(G2:G13) -> 0 | H14: =SUM(H2:H13) -> 0 | I14: m | J14: auto (based on formula) | N14: =N7 -> 144C/12T | O14: =SUM(P14:T14) -> 0 | P14: =ROUNDUP(((P7)+(P21*20))*1.05,0) -> 0 | Q14: =ROUNDUP(((Q7)+(Q21*20))*1.05,0) -> 0 | R14: =ROUNDUP(((R7)+(R21*20))*1.05,0) -> 0 | S14: =ROUNDUP(((S7)+(S21*20))*1.05,0) -> 0 | T14: =ROUNDUP(((T7)+(T21*20))*1.05,0) -> 0 | U14: m | V14: auto based on formula
B15: Rute Strand Wire | C15: =SUM(D15:H15) -> 0 | I15: m | J15: qty based on design | N15: =N8 -> 288C/24T | O15: =SUM(P15:T15) -> 0 | P15: =ROUNDUP(((P8)+(P22*20))*1.05,0) -> 0 | Q15: =ROUNDUP(((Q8)+(Q22*20))*1.05,0) -> 0 | R15: =ROUNDUP(((R8)+(R22*20))*1.05,0) -> 0 | S15: =ROUNDUP(((S8)+(S22*20))*1.05,0) -> 0 | T15: =ROUNDUP(((T8)+(T22*20))*1.05,0) -> 0 | U15: m | V15: auto based on formula
A16: Total Panjang Kabel (Slack + Toleransi 5%) | B16: =B2 -> Line A - 24C/2T | C16: =SUM(D16:H16) -> 0 | D16: =IF(D2=0,0,(ROUNDUP(((D2)+($D$44+$D$40)*20)*1.05,0))) -> 0 | E16: =IF(E2=0,0,(ROUNDUP(((E2)+($E$44+$E$40)*20)*1.05,0))) -> 0 | F16: =IF(F2=0,0,(ROUNDUP(((F2)+($F$44+$F$40)*20)*1.05,0))) -> 0 | G16: =IF(G2=0,0,(ROUNDUP(((G2)+($F$44+$F$40)*20)*1.05,0))) -> 0 | H16: =IF(H2=0,0,(ROUNDUP(((H2)+($F$44+$F$40)*20)*1.05,0))) -> 0 | I16: m | J16: auto (based on formula) | M16: Total Coil / Slack | N16: =N2 -> 24C/2T | O16: =SUM(P16:T16) -> 0 | P16: =IF(P2=0,0,(ROUNDUP((P2/400)+1,0))) -> 0 | Q16: =IF(Q2=0,0,(ROUNDUP((Q2/400)+1,0))) -> 0 | R16: =IF(R2=0,0,(ROUNDUP((R2/400)+1,0))) -> 0 | S16: =IF(S2=0,0,(ROUNDUP((S2/400)+1,0))) -> 0 | T16: =IF(T2=0,0,(ROUNDUP((T2/400)+1,0))) -> 0 | U16: pcs | V16: auto based on formula
B17: =B3 -> Line B - 24C/2T | C17: =SUM(D17:H17) -> 0 | D17: =IF(D3=0,0,(ROUNDUP(((D3)+($D$45+$D$41)*20)*1.05,0))) -> 0 | E17: =IF(E3=0,0,(ROUNDUP(((E3)+($E$45+$E$41)*20)*1.05,0))) -> 0 | F17: =IF(F3=0,0,(ROUNDUP(((F3)+($F$45+$F$41)*20)*1.05,0))) -> 0 | G17: =IF(G3=0,0,(ROUNDUP(((G3)+($F$45+$F$41)*20)*1.05,0))) -> 0 | H17: =IF(H3=0,0,(ROUNDUP(((H3)+($F$45+$F$41)*20)*1.05,0))) -> 0 | I17: m | J17: auto (based on formula) | N17: =N3 -> 36C/3T | O17: =SUM(P17:T17) -> 0 | P17: =IF(P3=0,0,(ROUNDUP((P3/400)+1,0))) -> 0 | Q17: =IF(Q3=0,0,(ROUNDUP((Q3/400)+1,0))) -> 0 | R17: =IF(R3=0,0,(ROUNDUP((R3/400)+1,0))) -> 0 | S17: =IF(S3=0,0,(ROUNDUP((S3/400)+1,0))) -> 0 | T17: =IF(T3=0,0,(ROUNDUP((T3/400)+1,0))) -> 0 | U17: pcs | V17: qty based on design
B18: =B4 -> Line C - 24C/2T | C18: =SUM(D18:H18) -> 0 | D18: =IF(D4=0,0,(ROUNDUP(((D4)+($D$46+$D$42)*20)*1.05,0))) -> 0 | E18: =IF(E4=0,0,(ROUNDUP(((E4)+($E$46+$E$42)*20)*1.05,0))) -> 0 | F18: =IF(F4=0,0,(ROUNDUP(((F4)+($F$46+$F$42)*20)*1.05,0))) -> 0 | G18: =IF(G4=0,0,(ROUNDUP(((G4)+($F$46+$F$42)*20)*1.05,0))) -> 0 | H18: =IF(H4=0,0,(ROUNDUP(((H4)+($F$46+$F$42)*20)*1.05,0))) -> 0 | I18: m | J18: auto (based on formula) | N18: =N4 -> 48C/4T | O18: =SUM(P18:T18) -> 0 | P18: =IF(P4=0,0,(ROUNDUP((P4/400)+1,0))) -> 0 | Q18: =IF(Q4=0,0,(ROUNDUP((Q4/400)+1,0))) -> 0 | R18: =IF(R4=0,0,(ROUNDUP((R4/400)+1,0))) -> 0 | S18: =IF(S4=0,0,(ROUNDUP((S4/400)+1,0))) -> 0 | T18: =IF(T4=0,0,(ROUNDUP((T4/400)+1,0))) -> 0 | U18: pcs | V18: qty based on design
B19: =B5 -> Line D - 24C/2T | C19: =SUM(D19:H19) -> 0 | D19: =IF(D5=0,0,(ROUNDUP(((D5)+($D$47+$D$43)*20)*1.05,0))) -> 0 | E19: =IF(E5=0,0,(ROUNDUP(((E5)+($E$47+$E$43)*20)*1.05,0))) -> 0 | F19: =IF(F5=0,0,(ROUNDUP(((F5)+($F$47+$F$43)*20)*1.05,0))) -> 0 | G19: =IF(G5=0,0,(ROUNDUP(((G5)+($F$47+$F$43)*20)*1.05,0))) -> 0 | H19: =IF(H5=0,0,(ROUNDUP(((H5)+($F$47+$F$43)*20)*1.05,0))) -> 0 | I19: m | J19: auto (based on formula) | N19: 72C/6T | O19: =SUM(P19:T19) -> 0 | P19: =IF(P5=0,0,(ROUNDUP((P5/400)+1,0))) -> 0 | Q19: =IF(Q5=0,0,(ROUNDUP((Q5/400)+1,0))) -> 0 | R19: =IF(R5=0,0,(ROUNDUP((R5/400)+1,0))) -> 0 | S19: =IF(S5=0,0,(ROUNDUP((S5/400)+1,0))) -> 0 | T19: =IF(T5=0,0,(ROUNDUP((T5/400)+1,0))) -> 0 | U19: pcs | V19: qty based on design
B20: =B6 -> Line A - 36C/3T | C20: =SUM(D20:H20) -> 0 | D20: =IF(D6=0,0,(ROUNDUP(((D6)+($D$44+$D$40)*20)*1.05,0))) -> 0 | E20: =IF(E6=0,0,(ROUNDUP(((E6)+($E$44+$E$40)*20)*1.05,0))) -> 0 | F20: =IF(F6=0,0,(ROUNDUP(((F6)+($F$44+$F$40)*20)*1.05,0))) -> 0 | G20: =IF(G6=0,0,(ROUNDUP(((G6)+($F$44+$F$40)*20)*1.05,0))) -> 0 | H20: =IF(H6=0,0,(ROUNDUP(((H6)+($F$44+$F$40)*20)*1.05,0))) -> 0 | I20: m | J20: auto (based on formula) | N20: 96C/8T | O20: =SUM(P20:T20) -> 0 | P20: =IF(P6=0,0,(ROUNDUP((P6/400)+1,0))) -> 0 | Q20: =IF(Q6=0,0,(ROUNDUP((Q6/400)+1,0))) -> 0 | R20: =IF(R6=0,0,(ROUNDUP((R6/400)+1,0))) -> 0 | S20: =IF(S6=0,0,(ROUNDUP((S6/400)+1,0))) -> 0 | T20: =IF(T6=0,0,(ROUNDUP((T6/400)+1,0))) -> 0 | U20: pcs | V20: qty based on design
B21: =B7 -> Line B - 36C/3T | C21: =SUM(D21:H21) -> 0 | D21: =IF(D7=0,0,(ROUNDUP(((D7)+($D$45+$D$41)*20)*1.05,0))) -> 0 | E21: =IF(E7=0,0,(ROUNDUP(((E7)+($E$45+$E$41)*20)*1.05,0))) -> 0 | F21: =IF(F7=0,0,(ROUNDUP(((F7)+($F$45+$F$41)*20)*1.05,0))) -> 0 | G21: =IF(G7=0,0,(ROUNDUP(((G7)+($F$45+$F$41)*20)*1.05,0))) -> 0 | H21: =IF(H7=0,0,(ROUNDUP(((H7)+($F$45+$F$41)*20)*1.05,0))) -> 0 | I21: m | J21: auto (based on formula) | N21: =N7 -> 144C/12T | O21: =SUM(P21:T21) -> 0 | P21: =IF(P7=0,0,(ROUNDUP((P7/400)+1,0))) -> 0 | Q21: =IF(Q7=0,0,(ROUNDUP((Q7/400)+1,0))) -> 0 | R21: =IF(R7=0,0,(ROUNDUP((R7/400)+1,0))) -> 0 | S21: =IF(S7=0,0,(ROUNDUP((S7/400)+1,0))) -> 0 | T21: =IF(T7=0,0,(ROUNDUP((T7/400)+1,0))) -> 0 | U21: pcs | V21: qty based on design
B22: =B8 -> Line C - 36C/3T | C22: =SUM(D22:H22) -> 0 | D22: =IF(D8=0,0,(ROUNDUP(((D8)+($D$46+$D$42)*20)*1.05,0))) -> 0 | E22: =IF(E8=0,0,(ROUNDUP(((E8)+($E$46+$E$42)*20)*1.05,0))) -> 0 | F22: =IF(F8=0,0,(ROUNDUP(((F8)+($F$46+$F$42)*20)*1.05,0))) -> 0 | G22: =IF(G8=0,0,(ROUNDUP(((G8)+($F$46+$F$42)*20)*1.05,0))) -> 0 | H22: =IF(H8=0,0,(ROUNDUP(((H8)+($F$46+$F$42)*20)*1.05,0))) -> 0 | I22: m | J22: auto (based on formula) | N22: =N8 -> 288C/24T | O22: =SUM(P22:T22) -> 0 | P22: =IF(P8=0,0,(ROUNDUP((P8/400)+1,0))) -> 0 | Q22: =IF(Q8=0,0,(ROUNDUP((Q8/400)+1,0))) -> 0 | R22: =IF(R8=0,0,(ROUNDUP((R8/400)+1,0))) -> 0 | S22: =IF(S8=0,0,(ROUNDUP((S8/400)+1,0))) -> 0 | T22: =IF(T8=0,0,(ROUNDUP((T8/400)+1,0))) -> 0 | U22: pcs | V22: qty based on design
B23: =B9 -> Line D - 36C/3T | C23: =SUM(D23:H23) -> 0 | D23: =IF(D9=0,0,(ROUNDUP(((D9)+($D$47+$D$43)*20)*1.05,0))) -> 0 | E23: =IF(E9=0,0,(ROUNDUP(((E9)+($E$47+$E$43)*20)*1.05,0))) -> 0 | F23: =IF(F9=0,0,(ROUNDUP(((F9)+($F$47+$F$43)*20)*1.05,0))) -> 0 | G23: =IF(G9=0,0,(ROUNDUP(((G9)+($F$47+$F$43)*20)*1.05,0))) -> 0 | H23: =IF(H9=0,0,(ROUNDUP(((H9)+($F$47+$F$43)*20)*1.05,0))) -> 0 | I23: m | J23: auto (based on formula) | M23: Closure | N23: Fiber Optic Joint Closure Type In-line 24 Core | O23: =SUM(P23:T23) -> 0 | P23: 0 | Q23: 0 | R23: 0 | S23: 0 | T23: 0 | U23: units | V23: qty based on design
B24: =B10 -> Line A - 48C/4T | C24: =SUM(D24:H24) -> 0 | D24: =IF(D10=0,0,(ROUNDUP(((D10)+($D$44+$D$40)*20)*1.05,0))) -> 0 | E24: =IF(E10=0,0,(ROUNDUP(((E10)+($E$44+$E$40)*20)*1.05,0))) -> 0 | F24: =IF(F10=0,0,(ROUNDUP(((F10)+($F$44+$F$40)*20)*1.05,0))) -> 0 | G24: =IF(G10=0,0,(ROUNDUP(((G10)+($F$44+$F$40)*20)*1.05,0))) -> 0 | H24: =IF(H10=0,0,(ROUNDUP(((H10)+($F$44+$F$40)*20)*1.05,0))) -> 0 | I24: m | J24: auto (based on formula) | N24: Fiber Optic Joint Closure Type In-line 36 Core | O24: =SUM(P24:T24) -> 0 | P24: 0 | Q24: 0 | R24: 0 | S24: 0 | T24: 0 | U24: units | V24: qty based on design
B25: =B11 -> Line B - 48C/4T | C25: =SUM(D25:H25) -> 0 | D25: =IF(D11=0,0,(ROUNDUP(((D11)+($D$45+$D$41)*20)*1.05,0))) -> 0 | E25: =IF(E11=0,0,(ROUNDUP(((E11)+($E$45+$E$41)*20)*1.05,0))) -> 0 | F25: =IF(F11=0,0,(ROUNDUP(((F11)+($F$45+$F$41)*20)*1.05,0))) -> 0 | G25: =IF(G11=0,0,(ROUNDUP(((G11)+($F$45+$F$41)*20)*1.05,0))) -> 0 | H25: =IF(H11=0,0,(ROUNDUP(((H11)+($F$45+$F$41)*20)*1.05,0))) -> 0 | I25: m | J25: auto (based on formula) | N25: Fiber Optic Joint Closure Type In-line 48 Core | O25: =SUM(P25:T25) -> 0 | P25: 0 | Q25: 0 | R25: 0 | S25: 0 | T25: 0 | U25: units | V25: qty based on design
B26: =B12 -> Line C - 48C/4T | C26: =SUM(D26:H26) -> 0 | D26: =IF(D12=0,0,(ROUNDUP(((D12)+($D$46+$D$42)*20)*1.05,0))) -> 0 | E26: =IF(E12=0,0,(ROUNDUP(((E12)+($E$46+$E$42)*20)*1.05,0))) -> 0 | F26: =IF(F12=0,0,(ROUNDUP(((F12)+($F$46+$F$42)*20)*1.05,0))) -> 0 | G26: =IF(G12=0,0,(ROUNDUP(((G12)+($F$46+$F$42)*20)*1.05,0))) -> 0 | H26: =IF(H12=0,0,(ROUNDUP(((H12)+($F$46+$F$42)*20)*1.05,0))) -> 0 | I26: m | J26: auto (based on formula) | N26: Fiber Optic Joint Closure Type In-line 72 Core | O26: =SUM(P26:T26) -> 0 | P26: 0 | Q26: 0 | R26: 0 | S26: 0 | T26: 0 | U26: units | V26: qty based on design
B27: =B13 -> Line D - 48C/4T | C27: =SUM(D27:H27) -> 0 | D27: =IF(D13=0,0,(ROUNDUP(((D13)+($D$47+$D$43)*20)*1.05,0))) -> 0 | E27: =IF(E13=0,0,(ROUNDUP(((E13)+($E$47+$E$43)*20)*1.05,0))) -> 0 | F27: =IF(F13=0,0,(ROUNDUP(((F13)+($F$47+$F$43)*20)*1.05,0))) -> 0 | G27: =IF(G13=0,0,(ROUNDUP(((G13)+($F$47+$F$43)*20)*1.05,0))) -> 0 | H27: =IF(H13=0,0,(ROUNDUP(((H13)+($F$47+$F$43)*20)*1.05,0))) -> 0 | I27: m | J27: auto (based on formula) | N27: Fiber Optic Joint Closure Type In-line 96 Core | O27: =SUM(P27:T27) -> 0 | P27: 0 | Q27: 0 | R27: 0 | S27: 0 | T27: 0 | U27: units | V27: qty based on design
A28: Total Panjang Cable | C28: =SUM(D28:H28) -> 0 | D28: =SUM(D16:D27) -> 0 | E28: =SUM(E16:E27) -> 0 | F28: =SUM(F16:F27) -> 0 | G28: =SUM(G16:G27) -> 0 | H28: =SUM(H16:H27) -> 0 | I28: m | J28: auto (based on formula) | N28: Fiber Optic Joint Closure Type In-line 144 Core | O28: =SUM(P28:T28) -> 0 | P28: 0 | Q28: 0 | R28: 0 | S28: 0 | T28: 0 | U28: units | V28: qty based on design
B29: Panjang Strand Wire + toleransi 5% | C29: =SUM(D29:H29) -> 0 | D29: =ROUNDUP(((D15*5%)+D15),0) -> 0 | E29: =ROUNDUP(((E15*5%)+E15),0) -> 0 | F29: =ROUNDUP(((F15*5%)+F15),0) -> 0 | G29: =ROUNDUP(((G15*5%)+G15),0) -> 0 | H29: =ROUNDUP(((H15*5%)+H15),0) -> 0 | I29: m | J29: auto (based on formula) | N29: Fiber Optic Joint Closure Type In-line 288 Core | O29: =SUM(P29:T29) -> 0 | P29: 0 | Q29: 0 | R29: 0 | S29: 0 | T29: 0 | U29: units | V29: qty based on design
A30: Total FDT Pole Mounted | B30: FDT Pole Mounted 48 core | C30: =SUM(D30:H30) -> 0 | D30: 0 | E30: 0 | F30: 0 | G30: 0 | H30: 0 | I30: set | J30: qty based on design | N30: Fiber Optic Joint Closure Type Dome 24 Core | O30: =SUM(P30:T30) -> 0 | P30: 0 | Q30: 0 | R30: 0 | S30: 0 | T30: 0 | U30: units | V30: qty based on design
B31: FDT Pole Mounted 72 core | C31: =SUM(D31:H31) -> 0 | D31: 0 | E31: 0 | F31: 0 | G31: 0 | H31: 0 | I31: set | J31: qty based on design | N31: Fiber Optic Joint Closure Type Dome 36 Core | O31: =SUM(P31:T31) -> 0 | P31: 0 | Q31: 0 | R31: 0 | S31: 0 | T31: 0 | U31: units | V31: auto based on formula
B32: FDT Pole Mounted 96 core | C32: =SUM(D32:H32) -> 0 | D32: 0 | E32: 0 | F32: 0 | G32: 0 | H32: 0 | I32: set | J32: qty based on design | N32: Fiber Optic Joint Closure Type Dome 48 Core | O32: =SUM(P32:T32) -> 0 | P32: 0 | Q32: 0 | R32: 0 | S32: 0 | T32: 0 | U32: units | V32: auto based on formula
B33: FDT Ground Mounted 144 core | C33: =SUM(D33:H33) -> 0 | D33: 0 | E33: 0 | F33: 0 | G33: 0 | H33: 0 | I33: set | J33: qty based on design | N33: Fiber Optic Joint Closure Type Dome 72 Core | O33: =SUM(P33:T33) -> 0 | P33: 0 | Q33: 0 | R33: 0 | S33: 0 | T33: 0 | U33: units | V33: auto based on formula
A34: Total Splitter | B34: Modular 1:8 di FDT | C34: =SUM(D34:H34) -> 0 | D34: =(ROUNDUP((D35/8),0)) -> 0 | E34: =(ROUNDUP((E35/8),0)) -> 0 | F34: =(ROUNDUP((F35/8),0)) -> 0 | G34: =(ROUNDUP((G35/8),0)) -> 0 | H34: =(ROUNDUP((H35/8),0)) -> 0 | I34: unit | J34: auto (based on formula) | N34: Fiber Optic Joint Closure Type Dome 96 Core | O34: =SUM(P34:T34) -> 0 | P34: 0 | Q34: 0 | R34: 0 | S34: 0 | T34: 0 | U34: units | V34: auto based on formula
B35: FAT 1:8 | C35: =SUM(D35:H35) -> 0 | D35: =SUM(D36:D39) -> 0 | E35: =SUM(E36:E39) -> 0 | F35: =SUM(F36:F39) -> 0 | G35: =SUM(G36:G39) -> 0 | H35: =SUM(H36:H39) -> 0 | I35: unit | J35: auto (based on formula) | N35: Fiber Optic Joint Closure Type Dome 144 Core | O35: =SUM(P35:T35) -> 0 | P35: 0 | Q35: 0 | R35: 0 | S35: 0 | T35: 0 | U35: units | V35: auto based on formula
A36: Total FAT | B36: Line A | C36: =SUM(D36:H36) -> 0 | D36: 0 | E36: 0 | F36: 0 | G36: 0 | H36: 0 | I36: unit | J36: qty based on design | N36: Fiber Optic Joint Closure Type Dome 288 Core | O36: =SUM(P36:T36) -> 0 | P36: 0 | Q36: 0 | R36: 0 | S36: 0 | T36: 0 | U36: units | V36: auto based on formula
B37: Line B | C37: =SUM(D37:H37) -> 0 | D37: 0 | E37: 0 | F37: 0 | G37: 0 | H37: 0 | I37: unit | J37: qty based on design | M37: Accessoris (1 set every acc) | N37: Cable loop holder/plat strip/Cable hanger | O37: =SUM(P37:T37) -> 0 | P37: =SUM(P16:P22) -> 0 | Q37: =SUM(Q16:Q22) -> 0 | R37: =SUM(R16:R22) -> 0 | S37: =SUM(S16:S22) -> 0 | T37: =SUM(T16:T22) -> 0 | U37: pcs | V37: qty based on design
B38: Line C | C38: =SUM(D38:H38) -> 0 | D38: 0 | E38: 0 | F38: 0 | G38: 0 | H38: 0 | I38: unit | J38: qty based on design | N38: 1. Plate belt 20mm | O38: =SUM(P38:T38) -> 0 | P38: =P37*4 -> 0 | Q38: =Q37*4 -> 0 | R38: =R37*4 -> 0 | S38: =S37*4 -> 0 | T38: =T37*4 -> 0 | U38: pcs | V38: auto based on formula
B39: Line D | C39: =SUM(D39:H39) -> 0 | D39: 0 | E39: 0 | F39: 0 | G39: 0 | H39: 0 | I39: unit | J39: qty based on design | N39: 2. Suspension clamp | O39: =SUM(P39:T39) -> 0 | P39: =ROUNDUP((SUM(P49,P52,P53,P54,P55,P58,P59)*20%),0) -> 0 | Q39: =ROUNDUP((SUM(Q49,Q52,Q53,Q54,Q55,Q58,Q59)*20%),0) -> 0 | R39: =ROUNDUP((SUM(R49,R52,R53,R54,R55,R58,R59)*20%),0) -> 0 | S39: =ROUNDUP((SUM(S49,S52,S53,S54,S55,S58,S59)*20%),0) -> 0 | T39: =ROUNDUP((SUM(T49,T52,T53,T54,T55,T58,T59)*20%),0) -> 0 | U39: pcs | V39: auto based on formula
A40: Total Slack di FDT | B40: =B36 -> Line A | C40: =SUM(D40:H40) -> 0 | D40: =IF(D36>=1,1,0) -> 0 | E40: =IF(E36>=1,1,0) -> 0 | F40: =IF(F36>=1,1,0) -> 0 | G40: =IF(G36>=1,1,0) -> 0 | H40: =IF(H36>=1,1,0) -> 0 | I40: slack | J40: auto (based on formula) | N40: 3. Buldog grip | O40: =SUM(P40:T40) -> 0 | P40: =(P48/40)*6 -> 0 | Q40: =(Q48/40)*6 -> 0 | R40: =(R48/40)*6 -> 0 | S40: =(S48/40)*6 -> 0 | T40: =(T48/40)*6 -> 0 | U40: pcs | V40: qty based on design
...
